2018-01-29 11:41:02,582 ERROR: Exception on /index [GET] [in /Users/lydiding/Desktop/microblog/venv/lib/python3.6/site-packages/flask/app.py:1560]
Traceback (most recent call last):
  File "/Users/lydiding/Desktop/microblog/venv/lib/python3.6/site-packages/flask/app.py", line 1982, in wsgi_app
    response = self.full_dispatch_request()
  File "/Users/lydiding/Desktop/microblog/venv/lib/python3.6/site-packages/flask/app.py", line 1614, in full_dispatch_request
    rv = self.handle_user_exception(e)
  File "/Users/lydiding/Desktop/microblog/venv/lib/python3.6/site-packages/flask/app.py", line 1517, in handle_user_exception
    reraise(exc_type, exc_value, tb)
  File "/Users/lydiding/Desktop/microblog/venv/lib/python3.6/site-packages/flask/_compat.py", line 33, in reraise
    raise value
  File "/Users/lydiding/Desktop/microblog/venv/lib/python3.6/site-packages/flask/app.py", line 1612, in full_dispatch_request
    rv = self.dispatch_request()
  File "/Users/lydiding/Desktop/microblog/venv/lib/python3.6/site-packages/flask/app.py", line 1598, in dispatch_request
    return self.view_functions[rule.endpoint](**req.view_args)
  File "/Users/lydiding/Desktop/microblog/venv/lib/python3.6/site-packages/flask_login/utils.py", line 261, in decorated_view
    return func(*args, **kwargs)
  File "/Users/lydiding/Desktop/microblog/app/routes.py", line 59, in index
    posts = posts.items, next_url = next_url, prev_url = prev_url)
  File "/Users/lydiding/Desktop/microblog/venv/lib/python3.6/site-packages/flask/templating.py", line 134, in render_template
    context, ctx.app)
  File "/Users/lydiding/Desktop/microblog/venv/lib/python3.6/site-packages/flask/templating.py", line 116, in _render
    rv = template.render(context)
  File "/Users/lydiding/Desktop/microblog/venv/lib/python3.6/site-packages/jinja2/asyncsupport.py", line 76, in render
    return original_render(self, *args, **kwargs)
  File "/Users/lydiding/Desktop/microblog/venv/lib/python3.6/site-packages/jinja2/environment.py", line 1008, in render
    return self.environment.handle_exception(exc_info, True)
  File "/Users/lydiding/Desktop/microblog/venv/lib/python3.6/site-packages/jinja2/environment.py", line 780, in handle_exception
    reraise(exc_type, exc_value, tb)
  File "/Users/lydiding/Desktop/microblog/venv/lib/python3.6/site-packages/jinja2/_compat.py", line 37, in reraise
    raise value.with_traceback(tb)
  File "/Users/lydiding/Desktop/microblog/app/templates/index.html", line 3, in top-level template code
    {% import 'bootstrap/wtf.html' as wtf %}
  File "/Users/lydiding/Desktop/microblog/app/templates/base.html", line 1, in top-level template code
    {% extends 'bootstrap/base.html' %}
  File "/Users/lydiding/Desktop/microblog/venv/lib/python3.6/site-packages/flask_bootstrap/templates/bootstrap/base.html", line 1, in top-level template code
    {% block doc -%}
  File "/Users/lydiding/Desktop/microblog/venv/lib/python3.6/site-packages/flask_bootstrap/templates/bootstrap/base.html", line 4, in block "doc"
    {%- block html %}
  File "/Users/lydiding/Desktop/microblog/venv/lib/python3.6/site-packages/flask_bootstrap/templates/bootstrap/base.html", line 20, in block "html"
    {% block body -%}
  File "/Users/lydiding/Desktop/microblog/venv/lib/python3.6/site-packages/flask_bootstrap/templates/bootstrap/base.html", line 21, in block "body"
    {% block navbar %}
  File "/Users/lydiding/Desktop/microblog/app/templates/base.html", line 41, in block "navbar"
    <li><a href="{{ url_for('user', username = current_user.username()) }}">Profile</a></li>
TypeError: 'str' object is not callable
2018-01-29 11:41:21,729 INFO: Microblog startup [in /Users/lydiding/Desktop/microblog/app/__init__.py:88]
2018-01-29 11:41:24,514 ERROR: Exception on /user/uchi [GET] [in /Users/lydiding/Desktop/microblog/venv/lib/python3.6/site-packages/flask/app.py:1560]
Traceback (most recent call last):
  File "/Users/lydiding/Desktop/microblog/venv/lib/python3.6/site-packages/flask/app.py", line 1982, in wsgi_app
    response = self.full_dispatch_request()
  File "/Users/lydiding/Desktop/microblog/venv/lib/python3.6/site-packages/flask/app.py", line 1614, in full_dispatch_request
    rv = self.handle_user_exception(e)
  File "/Users/lydiding/Desktop/microblog/venv/lib/python3.6/site-packages/flask/app.py", line 1517, in handle_user_exception
    reraise(exc_type, exc_value, tb)
  File "/Users/lydiding/Desktop/microblog/venv/lib/python3.6/site-packages/flask/_compat.py", line 33, in reraise
    raise value
  File "/Users/lydiding/Desktop/microblog/venv/lib/python3.6/site-packages/flask/app.py", line 1612, in full_dispatch_request
    rv = self.dispatch_request()
  File "/Users/lydiding/Desktop/microblog/venv/lib/python3.6/site-packages/flask/app.py", line 1598, in dispatch_request
    return self.view_functions[rule.endpoint](**req.view_args)
  File "/Users/lydiding/Desktop/microblog/venv/lib/python3.6/site-packages/flask_login/utils.py", line 261, in decorated_view
    return func(*args, **kwargs)
  File "/Users/lydiding/Desktop/microblog/app/routes.py", line 144, in user
    next_url = url_for("user", page = posts.next_num) if posts.has_next else None
  File "/Users/lydiding/Desktop/microblog/venv/lib/python3.6/site-packages/flask/helpers.py", line 333, in url_for
    return appctx.app.handle_url_build_error(error, endpoint, values)
  File "/Users/lydiding/Desktop/microblog/venv/lib/python3.6/site-packages/flask/app.py", line 1805, in handle_url_build_error
    reraise(exc_type, exc_value, tb)
  File "/Users/lydiding/Desktop/microblog/venv/lib/python3.6/site-packages/flask/_compat.py", line 33, in reraise
    raise value
  File "/Users/lydiding/Desktop/microblog/venv/lib/python3.6/site-packages/flask/helpers.py", line 323, in url_for
    force_external=external)
  File "/Users/lydiding/Desktop/microblog/venv/lib/python3.6/site-packages/werkzeug/routing.py", line 1776, in build
    raise BuildError(endpoint, values, method, self)
werkzeug.routing.BuildError: Could not build url for endpoint 'user' with values ['page']. Did you forget to specify values ['username']?
2018-01-29 11:43:32,111 INFO: Microblog startup [in /Users/lydiding/Desktop/microblog/app/__init__.py:88]
2018-01-29 11:46:38,392 INFO: Microblog startup [in /Users/lydiding/Desktop/microblog/app/__init__.py:88]
2018-01-29 11:48:07,707 INFO: Microblog startup [in /Users/lydiding/Desktop/microblog/app/__init__.py:88]
2018-01-29 11:50:57,860 INFO: Microblog startup [in /Users/lydiding/Desktop/microblog/app/__init__.py:88]
